Workbook
Name Analyst: Internal!$D$28:$H$28
Name Developer: Internal!$D$29:$I$29
Name Manager: Internal!$D$27:$I$27
Name Operator: Internal!$D$31:$J$31
Name Other: Internal!$D$32
Name Student: Internal!$D$26:$G$26
Name Tester: Internal!$D$30:$I$30

Sheet Copyright
B2: Copyright
B4: # Planning-Template.xlsx Copyright (C) 2012-2026 Rafael Corchuelo. In keeping with the traditional purpose of furthering education and research, it is the policy of the copyright owner to permit non-commercial use and redistribution of this software. It has been tested carefully, but it is not guaranteed for any particular purposes. The copyright owner does not offer any warranties or representations, nor do they accept any liabilities with respect to them.

Sheet Abstract
B2: Abstract
B4: This spreadsheet is intended to facilitate planning on the tasks of your project. Please, share it in your workgroup and closely follow the methodology taught.
C8: Help comments
C9: Enter configuration data in these cells
C10: Warning and error messages.
C11: Data computed automatically. Do not change them.
C12: Internal data. Do not change them.

Sheet D01
C2: Deliverable D01
C4: Use this form to document the tasks that you perform in your projects. Please, review the colour code in the "Abstract" sheet. In the exceptional case that you need to perform more tasks than expected, add them at the end.
C6: Costs | D6: Expected: | E6: =SUM(N11:N110) -> 2785
D7: Actual: | E7: =SUM(O11:O110) -> 2610
I9: Execution period | L9: Workload (in hours) | N9: Costs (in EUR)
B10: ORDER | C10: ID | D10: Type | E10: Assignee | F10: Role | G10: Activity | H10: Parent | I10: Start moment | J10: End moment | K10: Status | L10: Expected | M10: Actual | N10: Expected | O10: Actual | P10: Description
B11: 1 | C11: =IF(ISBLANK(D11), "", _xlfn.CONCAT("T", TEXT(B11, "0000"), "/", VLOOKUP(D11, Internal!$B$35:C$39, 2, FALSE), IF(OR(D11="QA", D11="Revision"), _xlfn.CONCAT("/", H11), ""))) -> T0001/M | D11: Management | E11: Student 4 | F11: Manager | G11: Other (Describe) | I11: 46054.958 | J11: 46055.01 | K11: =IF(OR(I11="",J11=""),"",IF(AND(J11<>"",I11>=NOW()),"Planned",IF(AND(J11<>"",J11<NOW()),"Completed","Ongoing"))) -> Completed | L11: 1 | M11: 1.25 | N11: =IF(ISBLANK(L11), "", L11*VLOOKUP($F11,Internal!$B$26:$C$32,2,FALSE)) -> 50 | O11: =IF(ISBLANK(M11), "", M11*VLOOKUP($F11,Internal!$B$26:$C$32,2,FALSE)) -> 62.5 | P11: Assigned a Student number to each member of the group
B12: 2 | C12: =IF(ISBLANK(D12), "", _xlfn.CONCAT("T", TEXT(B12, "0000"), "/", VLOOKUP(D12, Internal!$B$35:C$39, 2, FALSE), IF(OR(D12="QA", D12="Revision"), _xlfn.CONCAT("/", H12), ""))) -> T0002/D | D12: Development | E12: Student 4 | F12: Manager | G12: Initialise repository | I12: 46059.896 | J12: 46059.917 | K12: =IF(OR(I12="",J12=""),"",IF(AND(J12<>"",I12>=NOW()),"Planned",IF(AND(J12<>"",J12<NOW()),"Completed","Ongoing"))) -> Completed | L12: 0.5 | M12: 0.5 | N12: =IF(ISBLANK(L12), "", L12*VLOOKUP($F12,Internal!$B$26:$C$32,2,FALSE)) -> 25 | O12: =IF(ISBLANK(M12), "", M12*VLOOKUP($F12,Internal!$B$26:$C$32,2,FALSE)) -> 25
B13: 3 | C13: =IF(ISBLANK(D13), "", _xlfn.CONCAT("T", TEXT(B13, "0000"), "/", VLOOKUP(D13, Internal!$B$35:C$39, 2, FALSE), IF(OR(D13="QA", D13="Revision"), _xlfn.CONCAT("/", H13), ""))) -> T0003/D | D13: Development | E13: Student 4 | F13: Developer | G13: Customise the starter | I13: 46060.375 | J13: 46061.5 | K13: =IF(OR(I13="",J13=""),"",IF(AND(J13<>"",I13>=NOW()),"Planned",IF(AND(J13<>"",J13<NOW()),"Completed","Ongoing"))) -> Completed | L13: 1.5 | M13: 2 | N13: =IF(ISBLANK(L13), "", L13*VLOOKUP($F13,Internal!$B$26:$C$32,2,FALSE)) -> 37.5 | O13: =IF(ISBLANK(M13), "", M13*VLOOKUP($F13,Internal!$B$26:$C$32,2,FALSE)) -> 50
B14: 4 | C14: =IF(ISBLANK(D14), "", _xlfn.CONCAT("T", TEXT(B14, "0000"), "/", VLOOKUP(D14, Internal!$B$35:C$39, 2, FALSE), IF(OR(D14="QA", D14="Revision"), _xlfn.CONCAT("/", H14), ""))) -> T0004/M | D14: Management | E14: Student 4 | F14: Manager | G14: Write report | I14: 46062.688 | J14: 46062.833 | K14: =IF(OR(I14="",J14=""),"",IF(AND(J14<>"",I14>=NOW()),"Planned",IF(AND(J14<>"",J14<NOW()),"Completed","Ongoing"))) -> Completed | L14: 1 | M14: 0.5 | N14: =IF(ISBLANK(L14), "", L14*VLOOKUP($F14,Internal!$B$26:$C$32,2,FALSE)) -> 50 | O14: =IF(ISBLANK(M14), "", M14*VLOOKUP($F14,Internal!$B$26:$C$32,2,FALSE)) -> 25
B15: 5 | C15: =IF(ISBLANK(D15), "", _xlfn.CONCAT("T", TEXT(B15, "0000"), "/", VLOOKUP(D15, Internal!$B$35:C$39, 2, FALSE), IF(OR(D15="QA", D15="Revision"), _xlfn.CONCAT("/", H15), ""))) -> T0005/M | D15: Management | E15: Student 4 | F15: Manager | G15: Make plans | I15: 46062.5 | J15: 46062.531 | K15: =IF(OR(I15="",J15=""),"",IF(AND(J15<>"",I15>=NOW()),"Planned",IF(AND(J15<>"",J15<NOW()),"Completed","Ongoing"))) -> Completed | L15: 1.5 | M15: 0.75 | N15: =IF(ISBLANK(L15), "", L15*VLOOKUP($F15,Internal!$B$26:$C$32,2,FALSE)) -> 75 | O15: =IF(ISBLANK(M15), "", M15*VLOOKUP($F15,Internal!$B$26:$C$32,2,FALSE)) -> 37.5 | P15: Plan all Level Zero activities and Level C Information requirement activities
B16: 6 | C16: =IF(ISBLANK(D16), "", _xlfn.CONCAT("T", TEXT(B16, "0000"), "/", VLOOKUP(D16, Internal!$B$35:C$39, 2, FALSE), IF(OR(D16="QA", D16="Revision"), _xlfn.CONCAT("/", H16), ""))) -> T0006/D | D16: Development | E16: Student 2 | F16: Developer | G16: Create dev. config. | I16: 46062.5 | J16: 46060.729 | K16: =IF(OR(I16="",J16=""),"",IF(AND(J16<>"",I16>=NOW()),"Planned",IF(AND(J16<>"",J16<NOW()),"Completed","Ongoing"))) -> Completed | L16: 2 | M16: 2.5 | N16: =IF(ISBLANK(L16), "", L16*VLOOKUP($F16,Internal!$B$26:$C$32,2,FALSE)) -> 50 | O16: =IF(ISBLANK(M16), "", M16*VLOOKUP($F16,Internal!$B$26:$C$32,2,FALSE)) -> 62.5 | P16: Create admin accounts with credentials administrator1/administrator1 and administrator2/administrator2
B17: 7 | C17: =IF(ISBLANK(D17), "", _xlfn.CONCAT("T", TEXT(B17, "0000"), "/", VLOOKUP(D17, Internal!$B$35:C$39, 2, FALSE), IF(OR(D17="QA", D17="Revision"), _xlfn.CONCAT("/", H17), ""))) -> T0007/D | D17: Development | E17: Student 1 | F17: Developer | G17: Implement feature | I17: 46062.5 | J17: 46062.729 | K17: =IF(OR(I17="",J17=""),"",IF(AND(J17<>"",I17>=NOW()),"Planned",IF(AND(J17<>"",J17<NOW()),"Completed","Ongoing"))) -> Completed | L17: 2 | M17: 2 | N17: =IF(ISBLANK(L17), "", L17*VLOOKUP($F17,Internal!$B$26:$C$32,2,FALSE)) -> 50 | O17: =IF(ISBLANK(M17), "", M17*VLOOKUP($F17,Internal!$B$26:$C$32,2,FALSE)) -> 50 | P17: Implement constraints ValidHeader, ValidText and ValidTicker (Model-CG.ufx)
B18: 8 | C18: =IF(ISBLANK(D18), "", _xlfn.CONCAT("T", TEXT(B18, "0000"), "/", VLOOKUP(D18, Internal!$B$35:C$39, 2, FALSE), IF(OR(D18="QA", D18="Revision"), _xlfn.CONCAT("/", H18), ""))) -> T0008/QA/ | D18: QA | E18: Student 5 | F18: Tester | G18: Check deliverable | I18: 46062.5 | J18: 46062.729 | K18: =IF(OR(I18="",J18=""),"",IF(AND(J18<>"",I18>=NOW()),"Planned",IF(AND(J18<>"",J18<NOW()),"Completed","Ongoing"))) -> Completed | L18: 1 | M18: 1 | N18: =IF(ISBLANK(L18), "", L18*VLOOKUP($F18,Internal!$B$26:$C$32,2,FALSE)) -> 30 | O18: =IF(ISBLANK(M18), "", M18*VLOOKUP($F18,Internal!$B$26:$C$32,2,FALSE)) -> 30 | P18: Double check that the deliverable achieves all Zero Level requirements
B19: 9 | C19: =IF(ISBLANK(D19), "", _xlfn.CONCAT("T", TEXT(B19, "0000"), "/", VLOOKUP(D19, Internal!$B$35:C$39, 2, FALSE), IF(OR(D19="QA", D19="Revision"), _xlfn.CONCAT("/", H19), ""))) -> T0009/O | D19: Other | E19: ALL | F19: Student | G19: Attend lecture | I19: 46062.646 | J19: 46062.729 | K19: =IF(OR(I19="",J19=""),"",IF(AND(J19<>"",I19>=NOW()),"Planned",IF(AND(J19<>"",J19<NOW()),"Completed","Ongoing"))) -> Completed | L19: 2 | M19: 2 | N19: =IF(ISBLANK(L19), "", L19*VLOOKUP($F19,Internal!$B$26:$C$32,2,FALSE)) -> 0 | O19: =IF(ISBLANK(M19), "", M19*VLOOKUP($F19,Internal!$B$26:$C$32,2,FALSE)) -> 0
B20: 10 | C20: =IF(ISBLANK(D20), "", _xlfn.CONCAT("T", TEXT(B20, "0000"), "/", VLOOKUP(D20, Internal!$B$35:C$39, 2, FALSE), IF(OR(D20="QA", D20="Revision"), _xlfn.CONCAT("/", H20), ""))) -> T0010/O | D20: Other | E20: ALL | F20: Student | G20: Attend lecture | I20: 46065.736 | J20: 46065.812 | K20: =IF(OR(I20="",J20=""),"",IF(AND(J20<>"",I20>=NOW()),"Planned",IF(AND(J20<>"",J20<NOW()),"Completed","Ongoing"))) -> Completed | L20: 2 | M20: 2 | N20: =IF(ISBLANK(L20), "", L20*VLOOKUP($F20,Internal!$B$26:$C$32,2,FALSE)) -> 0 | O20: =IF(ISBLANK(M20), "", M20*VLOOKUP($F20,Internal!$B$26:$C$32,2,FALSE)) -> 0
B21: 11 | C21: =IF(ISBLANK(D21), "", _xlfn.CONCAT("T", TEXT(B21, "0000"), "/", VLOOKUP(D21, Internal!$B$35:C$39, 2, FALSE), IF(OR(D21="QA", D21="Revision"), _xlfn.CONCAT("/", H21), ""))) -> T0011/M | D21: Management | E21: Student 4 | F21: Manager | G21: Make plans | I21: 46065.833 | J21: 46067.646 | K21: =IF(OR(I21="",J21=""),"",IF(AND(J21<>"",I21>=NOW()),"Planned",IF(AND(J21<>"",J21<NOW()),"Completed","Ongoing"))) -> Completed | L21: 1.5 | M21: 1.25 | N21: =IF(ISBLANK(L21), "", L21*VLOOKUP($F21,Internal!$B$26:$C$32,2,FALSE)) -> 75 | O21: =IF(ISBLANK(M21), "", M21*VLOOKUP($F21,Internal!$B$26:$C$32,2,FALSE)) -> 62.5 | P21: Plan and manage planning sheet for C Level requirements
B22: 12 | C22: =IF(ISBLANK(D22), "", _xlfn.CONCAT("T", TEXT(B22, "0000"), "/", VLOOKUP(D22, Internal!$B$35:C$39, 2, FALSE), IF(OR(D22="QA", D22="Revision"), _xlfn.CONCAT("/", H22), ""))) -> T0012/D | D22: Development | E22: Student 1 | F22: Developer | G22: Implement feature | I22: 46065.833 | J22: 46069.646 | K22: =IF(OR(I22="",J22=""),"",IF(AND(J22<>"",I22>=NOW()),"Planned",IF(AND(J22<>"",J22<NOW()),"Completed","Ongoing"))) -> Completed | L22: 1.5 | M22: 1.5 | N22: =IF(ISBLANK(L22), "", L22*VLOOKUP($F22,Internal!$B$26:$C$32,2,FALSE)) -> 37.5 | O22: =IF(ISBLANK(M22), "", M22*VLOOKUP($F22,Internal!$B$26:$C$32,2,FALSE)) -> 37.5 | P22: Implement the data model sketched in file "Model-C01.uxf" (S1/1)
B23: 13 | C23: =IF(ISBLANK(D23), "", _xlfn.CONCAT("T", TEXT(B23, "0000"), "/", VLOOKUP(D23, Internal!$B$35:C$39, 2, FALSE), IF(OR(D23="QA", D23="Revision"), _xlfn.CONCAT("/", H23), ""))) -> T0013/D | D23: Development | E23: Student 2 | F23: Developer | G23: Implement feature | I23: 46065.833 | J23: 46069.646 | K23: =IF(OR(I23="",J23=""),"",IF(AND(J23<>"",I23>=NOW()),"Planned",IF(AND(J23<>"",J23<NOW()),"Completed","Ongoing"))) -> Completed | L23: 1.5 | M23: 1.5 | N23: =IF(ISBLANK(L23), "", L23*VLOOKUP($F23,Internal!$B$26:$C$32,2,FALSE)) -> 37.5 | O23: =IF(ISBLANK(M23), "", M23*VLOOKUP($F23,Internal!$B$26:$C$32,2,FALSE)) -> 37.5 | P23: Implement the data model sketched in file "Model-C02.uxf" (S2/1)
B24: 14 | C24: =IF(ISBLANK(D24), "", _xlfn.CONCAT("T", TEXT(B24, "0000"), "/", VLOOKUP(D24, Internal!$B$35:C$39, 2, FALSE), IF(OR(D24="QA", D24="Revision"), _xlfn.CONCAT("/", H24), ""))) -> T0014/D | D24: Development | E24: Student 3 | F24: Developer | G24: Implement feature | I24: 46065.833 | J24: 46069.646 | K24: =IF(OR(I24="",J24=""),"",IF(AND(J24<>"",I24>=NOW()),"Planned",IF(AND(J24<>"",J24<NOW()),"Completed","Ongoing"))) -> Completed | L24: 1.5 | M24: 1.25 | N24: =IF(ISBLANK(L24), "", L24*VLOOKUP($F24,Internal!$B$26:$C$32,2,FALSE)) -> 37.5 | O24: =IF(ISBLANK(M24), "", M24*VLOOKUP($F24,Internal!$B$26:$C$32,2,FALSE)) -> 31.25 | P24: Implement the data model sketched in file "Model-C03.uxf" (S3/1)
B25: 15 | C25: =IF(ISBLANK(D25), "", _xlfn.CONCAT("T", TEXT(B25, "0000"), "/", VLOOKUP(D25, Internal!$B$35:C$39, 2, FALSE), IF(OR(D25="QA", D25="Revision"), _xlfn.CONCAT("/", H25), ""))) -> T0015/D | D25: Development | E25: Student 4 | F25: Developer | G25: Implement feature | I25: 46065.833 | J25: 46069.646 | K25: =IF(OR(I25="",J25=""),"",IF(AND(J25<>"",I25>=NOW()),"Planned",IF(AND(J25<>"",J25<NOW()),"Completed","Ongoing"))) -> Completed | L25: 1.5 | M25: 1.75 | N25: =IF(ISBLANK(L25), "", L25*VLOOKUP($F25,Internal!$B$26:$C$32,2,FALSE)) -> 37.5 | O25: =IF(ISBLANK(M25), "", M25*VLOOKUP($F25,Internal!$B$26:$C$32,2,FALSE)) -> 43.75 | P25: Implement the data model sketched in file "Model-C04.uxf" (S4/1)
B26: 16 | C26: =IF(ISBLANK(D26), "", _xlfn.CONCAT("T", TEXT(B26, "0000"), "/", VLOOKUP(D26, Internal!$B$35:C$39, 2, FALSE), IF(OR(D26="QA", D26="Revision"), _xlfn.CONCAT("/", H26), ""))) -> T0016/D | D26: Development | E26: Student 5 | F26: Developer | G26: Implement feature | I26: 46065.833 | J26: 46069.646 | K26: =IF(OR(I26="",J26=""),"",IF(AND(J26<>"",I26>=NOW()),"Planned",IF(AND(J26<>"",J26<NOW()),"Completed","Ongoing"))) -> Completed | L26: 1.5 | M26: 1.25 | N26: =IF(ISBLANK(L26), "", L26*VLOOKUP($F26,Internal!$B$26:$C$32,2,FALSE)) -> 37.5 | O26: =IF(ISBLANK(M26), "", M26*VLOOKUP($F26,Internal!$B$26:$C$32,2,FALSE)) -> 31.25 | P26: Implement the data model sketched in file "Model-C05.uxf" (S5/1)
B27: 17 | C27: =IF(ISBLANK(D27), "", _xlfn.CONCAT("T", TEXT(B27, "0000"), "/", VLOOKUP(D27, Internal!$B$35:C$39, 2, FALSE), IF(OR(D27="QA", D27="Revision"), _xlfn.CONCAT("/", H27), ""))) -> T0017/O | D27: Other | E27: ALL | F27: Student | G27: Attend lecture | I27: 46069.646 | J27: 46069.722 | K27: =IF(OR(I27="",J27=""),"",IF(AND(J27<>"",I27>=NOW()),"Planned",IF(AND(J27<>"",J27<NOW()),"Completed","Ongoing"))) -> Completed | L27: 2 | M27: 2 | N27: =IF(ISBLANK(L27), "", L27*VLOOKUP($F27,Internal!$B$26:$C$32,2,FALSE)) -> 0 | O27: =IF(ISBLANK(M27), "", M27*VLOOKUP($F27,Internal!$B$26:$C$32,2,FALSE)) -> 0
B28: 18 | C28: =IF(ISBLANK(D28), "", _xlfn.CONCAT("T", TEXT(B28, "0000"), "/", VLOOKUP(D28, Internal!$B$35:C$39, 2, FALSE), IF(OR(D28="QA", D28="Revision"), _xlfn.CONCAT("/", H28), ""))) -> T0018/O | D28: Other | E28: ALL | F28: Student | G28: Attend lecture | I28: 46072.736 | J28: 46072.812 | K28: =IF(OR(I28="",J28=""),"",IF(AND(J28<>"",I28>=NOW()),"Planned",IF(AND(J28<>"",J28<NOW()),"Completed","Ongoing"))) -> Completed | L28: 2 | M28: 2 | N28: =IF(ISBLANK(L28), "", L28*VLOOKUP($F28,Internal!$B$26:$C$32,2,FALSE)) -> 0 | O28: =IF(ISBLANK(M28), "", M28*VLOOKUP($F28,Internal!$B$26:$C$32,2,FALSE)) -> 0
B29: 19 | C29: =IF(ISBLANK(D29), "", _xlfn.CONCAT("T", TEXT(B29, "0000"), "/", VLOOKUP(D29, Internal!$B$35:C$39, 2, FALSE), IF(OR(D29="QA", D29="Revision"), _xlfn.CONCAT("/", H29), ""))) -> T0019/O | D29: Other | E29: ALL | F29: Student | G29: Attend lecture | I29: 46076.646 | J29: 46076.722 | K29: =IF(OR(I29="",J29=""),"",IF(AND(J29<>"",I29>=NOW()),"Planned",IF(AND(J29<>"",J29<NOW()),"Completed","Ongoing"))) -> Completed | L29: 2 | M29: 2 | N29: =IF(ISBLANK(L29), "", L29*VLOOKUP($F29,Internal!$B$26:$C$32,2,FALSE)) -> 0 | O29: =IF(ISBLANK(M29), "", M29*VLOOKUP($F29,Internal!$B$26:$C$32,2,FALSE)) -> 0
B30: 20 | C30: =IF(ISBLANK(D30), "", _xlfn.CONCAT("T", TEXT(B30, "0000"), "/", VLOOKUP(D30, Internal!$B$35:C$39, 2, FALSE), IF(OR(D30="QA", D30="Revision"), _xlfn.CONCAT("/", H30), ""))) -> T0020/O | D30: Other | E30: ALL | F30: Student | G30: Attend lecture | I30: 46079.736 | J30: 46079.812 | K30: =IF(OR(I30="",J30=""),"",IF(AND(J30<>"",I30>=NOW()),"Planned",IF(AND(J30<>"",J30<NOW()),"Completed","Ongoing"))) -> Completed | L30: 2 | M30: 2 | N30: =IF(ISBLANK(L30), "", L30*VLOOKUP($F30,Internal!$B$26:$C$32,2,FALSE)) -> 0 | O30: =IF(ISBLANK(M30), "", M30*VLOOKUP($F30,Internal!$B$26:$C$32,2,FALSE)) -> 0
B31: 21 | C31: =IF(ISBLANK(D31), "", _xlfn.CONCAT("T", TEXT(B31, "0000"), "/", VLOOKUP(D31, Internal!$B$35:C$39, 2, FALSE), IF(OR(D31="QA", D31="Revision"), _xlfn.CONCAT("/", H31), ""))) -> T0021/QA/T0012/D | D31: QA | E31: Student 1 | F31: Tester | G31: Other (Describe) | H31: T0012/D | I31: 46072.833 | J31: 46076.646 | K31: =IF(OR(I31="",J31=""),"",IF(AND(J31<>"",I31>=NOW()),"Planned",IF(AND(J31<>"",J31<NOW()),"Completed","Ongoing"))) -> Completed | L31: 2 | M31: 2.25 | N31: =IF(ISBLANK(L31), "", L31*VLOOKUP($F31,Internal!$B$26:$C$32,2,FALSE)) -> 60 | O31: =IF(ISBLANK(M31), "", M31*VLOOKUP($F31,Internal!$B$26:$C$32,2,FALSE)) -> 67.5 | P31: Populate the "sample" csv files referring "Model-C01.uxf" and create the corresponding user accounts
B32: 22 | C32: =IF(ISBLANK(D32), "", _xlfn.CONCAT("T", TEXT(B32, "0000"), "/", VLOOKUP(D32, Internal!$B$35:C$39, 2, FALSE), IF(OR(D32="QA", D32="Revision"), _xlfn.CONCAT("/", H32), ""))) -> T0022/QA/T0013/D | D32: QA | E32: Student 2 | F32: Tester | G32: Other (Describe) | H32: T0013/D | I32: 46072.833 | J32: 46076.646 | K32: =IF(OR(I32="",J32=""),"",IF(AND(J32<>"",I32>=NOW()),"Planned",IF(AND(J32<>"",J32<NOW()),"Completed","Ongoing"))) -> Completed | L32: 2 | M32: 1.5 | N32: =IF(ISBLANK(L32), "", L32*VLOOKUP($F32,Internal!$B$26:$C$32,2,FALSE)) -> 60 | O32: =IF(ISBLANK(M32), "", M32*VLOOKUP($F32,Internal!$B$26:$C$32,2,FALSE)) -> 45 | P32: Populate the "sample" csv files referring "Model-C02.uxf" and create the corresponding user accounts
B33: 23 | C33: =IF(ISBLANK(D33), "", _xlfn.CONCAT("T", TEXT(B33, "0000"), "/", VLOOKUP(D33, Internal!$B$35:C$39, 2, FALSE), IF(OR(D33="QA", D33="Revision"), _xlfn.CONCAT("/", H33), ""))) -> T0023/QA/T0014/D | D33: QA | E33: Student 3 | F33: Tester | G33: Other (Describe) | H33: T0014/D | I33: 46072.833 | J33: 46076.646 | K33: =IF(OR(I33="",J33=""),"",IF(AND(J33<>"",I33>=NOW()),"Planned",IF(AND(J33<>"",J33<NOW()),"Completed","Ongoing"))) -> Completed | L33: 2 | M33: 1.75 | N33: =IF(ISBLANK(L33), "", L33*VLOOKUP($F33,Internal!$B$26:$C$32,2,FALSE)) -> 60 | O33: =IF(ISBLANK(M33), "", M33*VLOOKUP($F33,Internal!$B$26:$C$32,2,FALSE)) -> 52.5 | P33: Populate the "sample" csv files referring "Model-C03.uxf" and create the corresponding user accounts
B34: 24 | C34: =IF(ISBLANK(D34), "", _xlfn.CONCAT("T", TEXT(B34, "0000"), "/", VLOOKUP(D34, Internal!$B$35:C$39, 2, FALSE), IF(OR(D34="QA", D34="Revision"), _xlfn.CONCAT("/", H34), ""))) -> T0024/QA/T0015/D | D34: QA | E34: Student 4 | F34: Tester | G34: Other (Describe) | H34: T0015/D | I34: 46072.833 | J34: 46076.646 | K34: =IF(OR(I34="",J34=""),"",IF(AND(J34<>"",I34>=NOW()),"Planned",IF(AND(J34<>"",J34<NOW()),"Completed","Ongoing"))) -> Completed | L34: 2 | M34: 2 | N34: =IF(ISBLANK(L34), "", L34*VLOOKUP($F34,Internal!$B$26:$C$32,2,FALSE)) -> 60 | O34: =IF(ISBLANK(M34), "", M34*VLOOKUP($F34,Internal!$B$26:$C$32,2,FALSE)) -> 60 | P34: Populate the "sample" csv files referring "Model-C04.uxf" and create the corresponding user accounts
B35: 25 | C35: =IF(ISBLANK(D35), "", _xlfn.CONCAT("T", TEXT(B35, "0000"), "/", VLOOKUP(D35, Internal!$B$35:C$39, 2, FALSE), IF(OR(D35="QA", D35="Revision"), _xlfn.CONCAT("/", H35), ""))) -> T0025/QA/T0016/D | D35: QA | E35: Student 5 | F35: Tester | G35: Other (Describe) | H35: T0016/D | I35: 46072.833 | J35: 46076.646 | K35: =IF(OR(I35="",J35=""),"",IF(AND(J35<>"",I35>=NOW()),"Planned",IF(AND(J35<>"",J35<NOW()),"Completed","Ongoing"))) -> Completed | L35: 2 | M35: 2 | N35: =IF(ISBLANK(L35), "", L35*VLOOKUP($F35,Internal!$B$26:$C$32,2,FALSE)) -> 60 | O35: =IF(ISBLANK(M35), "", M35*VLOOKUP($F35,Internal!$B$26:$C$32,2,FALSE)) -> 60 | P35: Populate the "sample" csv files referring "Model-C05.uxf" and create the corresponding user accounts
B36: 26 | C36: =IF(ISBLANK(D36), "", _xlfn.CONCAT("T", TEXT(B36, "0000"), "/", VLOOKUP(D36, Internal!$B$35:C$39, 2, FALSE), IF(OR(D36="QA", D36="Revision"), _xlfn.CONCAT("/", H36), ""))) -> T0026/O | D36: Other | E36: ALL | F36: Student | G36: Attend lecture | I36: 46083.646 | J36: 46083.736 | K36: =IF(OR(I36="",J36=""),"",IF(AND(J36<>"",I36>=NOW()),"Planned",IF(AND(J36<>"",J36<NOW()),"Completed","Ongoing"))) -> Completed | L36: 2 | M36: 2 | N36: =IF(ISBLANK(L36), "", L36*VLOOKUP($F36,Internal!$B$26:$C$32,2,FALSE)) -> 0 | O36: =IF(ISBLANK(M36), "", M36*VLOOKUP($F36,Internal!$B$26:$C$32,2,FALSE)) -> 0
B37: 27 | C37: =IF(ISBLANK(D37), "", _xlfn.CONCAT("T", TEXT(B37, "0000"), "/", VLOOKUP(D37, Internal!$B$35:C$39, 2, FALSE), IF(OR(D37="QA", D37="Revision"), _xlfn.CONCAT("/", H37), ""))) -> T0027/O | D37: Other | E37: ALL | F37: Student | G37: Attend lecture | I37: 46086.736 | J37: 46086.812 | K37: =IF(OR(I37="",J37=""),"",IF(AND(J37<>"",I37>=NOW()),"Planned",IF(AND(J37<>"",J37<NOW()),"Completed","Ongoing"))) -> Completed | L37: 2 | M37: 2 | N37: =IF(ISBLANK(L37), "", L37*VLOOKUP($F37,Internal!$B$26:$C$32,2,FALSE)) -> 0 | O37: =IF(ISBLANK(M37), "", M37*VLOOKUP($F37,Internal!$B$26:$C$32,2,FALSE)) -> 0
B38: 28 | C38: =IF(ISBLANK(D38), "", _xlfn.CONCAT("T", TEXT(B38, "0000"), "/", VLOOKUP(D38, Internal!$B$35:C$39, 2, FALSE), IF(OR(D38="QA", D38="Revision"), _xlfn.CONCAT("/", H38), ""))) -> T0028/QA/T0021/QA/T0012/D | D38: QA | E38: Student 1 | F38: Tester | G38: Other (Describe) | H38: T0021/QA/T0012/D | I38: 46076.833 | J38: 46083.646 | K38: =IF(OR(I38="",J38=""),"",IF(AND(J38<>"",I38>=NOW()),"Planned",IF(AND(J38<>"",J38<NOW()),"Completed","Ongoing"))) -> Completed | L38: 2.5 | M38: 2.25 | N38: =IF(ISBLANK(L38), "", L38*VLOOKUP($F38,Internal!$B$26:$C$32,2,FALSE)) -> 75 | O38: =IF(ISBLANK(M38), "", M38*VLOOKUP($F38,Internal!$B$26:$C$32,2,FALSE)) -> 67.5 | P38: Populate the "errata" csv files referring "Model-C01.uxf" (S1/6)
B39: 29 | C39: =IF(ISBLANK(D39), "", _xlfn.CONCAT("T", TEXT(B39, "0000"), "/", VLOOKUP(D39, Internal!$B$35:C$39, 2, FALSE), IF(OR(D39="QA", D39="Revision"), _xlfn.CONCAT("/", H39), ""))) -> T0029/QA/T0022/QA/T0013/D | D39: QA | E39: Student 2 | F39: Tester | G39: Other (Describe) | H39: T0022/QA/T0013/D | I39: 46076.833 | J39: 46083.646 | K39: =IF(OR(I39="",J39=""),"",IF(AND(J39<>"",I39>=NOW()),"Planned",IF(AND(J39<>"",J39<NOW()),"Completed","Ongoing"))) -> Completed | L39: 2.5 | M39: 2 | N39: =IF(ISBLANK(L39), "", L39*VLOOKUP($F39,Internal!$B$26:$C$32,2,FALSE)) -> 75 | O39: =IF(ISBLANK(M39), "", M39*VLOOKUP($F39,Internal!$B$26:$C$32,2,FALSE)) -> 60 | P39: Populate the "errata" csv files referring "Model-C02.uxf" (S2/6)
B40: 30 | C40: =IF(ISBLANK(D40), "", _xlfn.CONCAT("T", TEXT(B40, "0000"), "/", VLOOKUP(D40, Internal!$B$35:C$39, 2, FALSE), IF(OR(D40="QA", D40="Revision"), _xlfn.CONCAT("/", H40), ""))) -> T0030/QA/T0023/QA/T0014/D | D40: QA | E40: Student 3 | F40: Tester | G40: Other (Describe) | H40: T0023/QA/T0014/D | I40: 46076.833 | J40: 46083.646 | K40: =IF(OR(I40="",J40=""),"",IF(AND(J40<>"",I40>=NOW()),"Planned",IF(AND(J40<>"",J40<NOW()),"Completed","Ongoing"))) -> Completed | L40: 2.5 | M40: 2.75 | N40: =IF(ISBLANK(L40), "", L40*VLOOKUP($F40,Internal!$B$26:$C$32,2,FALSE)) -> 75 | O40: =IF(ISBLANK(M40), "", M40*VLOOKUP($F40,Internal!$B$26:$C$32,2,FALSE)) -> 82.5 | P40: Populate the "errata" csv files referring "Model-C03.uxf" (S3/6)
B41: 31 | C41: =IF(ISBLANK(D41), "", _xlfn.CONCAT("T", TEXT(B41, "0000"), "/", VLOOKUP(D41, Internal!$B$35:C$39, 2, FALSE), IF(OR(D41="QA", D41="Revision"), _xlfn.CONCAT("/", H41), ""))) -> T0031/QA/T0024/QA/T0015/D | D41: QA | E41: Student 4 | F41: Tester | G41: Other (Describe) | H41: T0024/QA/T0015/D | I41: 46076.833 | J41: 46083.646 | K41: =IF(OR(I41="",J41=""),"",IF(AND(J41<>"",I41>=NOW()),"Planned",IF(AND(J41<>"",J41<NOW()),"Completed","Ongoing"))) -> Completed | L41: 2.5 | M41: 1.5 | N41: =IF(ISBLANK(L41), "", L41*VLOOKUP($F41,Internal!$B$26:$C$32,2,FALSE)) -> 75 | O41: =IF(ISBLANK(M41), "", M41*VLOOKUP($F41,Internal!$B$26:$C$32,2,FALSE)) -> 45 | P41: Populate the "errata" csv files referring "Model-C04.uxf" (S4/6)
B42: 32 | C42: =IF(ISBLANK(D42), "", _xlfn.CONCAT("T", TEXT(B42, "0000"), "/", VLOOKUP(D42, Internal!$B$35:C$39, 2, FALSE), IF(OR(D42="QA", D42="Revision"), _xlfn.CONCAT("/", H42), ""))) -> T0032/QA/T0025/QA/T0016/D | D42: QA | E42: Student 5 | F42: Tester | G42: Other (Describe) | H42: T0025/QA/T0016/D | I42: 46076.833 | J42: 46083.646 | K42: =IF(OR(I42="",J42=""),"",IF(AND(J42<>"",I42>=NOW()),"Planned",IF(AND(J42<>"",J42<NOW()),"Completed","Ongoing"))) -> Completed | L42: 2.5 | M42: 2.75 | N42: =IF(ISBLANK(L42), "", L42*VLOOKUP($F42,Internal!$B$26:$C$32,2,FALSE)) -> 75 | O42: =IF(ISBLANK(M42), "", M42*VLOOKUP($F42,Internal!$B$26:$C$32,2,FALSE)) -> 82.5 | P42: Populate the "errata" csv files referring "Model-C05.uxf" (S5/6)
B43: 33 | C43: =IF(ISBLANK(D43), "", _xlfn.CONCAT("T", TEXT(B43, "0000"), "/", VLOOKUP(D43, Internal!$B$35:C$39, 2, FALSE), IF(OR(D43="QA", D43="Revision"), _xlfn.CONCAT("/", H43), ""))) -> T0033/O | D43: Other | E43: ALL | F43: Student | G43: Attend lecture | I43: 46090.646 | J43: 46090.722 | K43: =IF(OR(I43="",J43=""),"",IF(AND(J43<>"",I43>=NOW()),"Planned",IF(AND(J43<>"",J43<NOW()),"Completed","Ongoing"))) -> Completed | L43: 2 | M43: 2 | N43: =IF(ISBLANK(L43), "", L43*VLOOKUP($F43,Internal!$B$26:$C$32,2,FALSE)) -> 0 | O43: =IF(ISBLANK(M43), "", M43*VLOOKUP($F43,Internal!$B$26:$C$32,2,FALSE)) -> 0
B44: 34 | C44: =IF(ISBLANK(D44), "", _xlfn.CONCAT("T", TEXT(B44, "0000"), "/", VLOOKUP(D44, Internal!$B$35:C$39, 2, FALSE), IF(OR(D44="QA", D44="Revision"), _xlfn.CONCAT("/", H44), ""))) -> T0034/O | D44: Other | E44: ALL | F44: Student | G44: Attend lecture | I44: 46093.736 | J44: 46093.812 | K44: =IF(OR(I44="",J44=""),"",IF(AND(J44<>"",I44>=NOW()),"Planned",IF(AND(J44<>"",J44<NOW()),"Completed","Ongoing"))) -> Completed | L44: 2 | M44: 2 | N44: =IF(ISBLANK(L44), "", L44*VLOOKUP($F44,Internal!$B$26:$C$32,2,FALSE)) -> 0 | O44: =IF(ISBLANK(M44), "", M44*VLOOKUP($F44,Internal!$B$26:$C$32,2,FALSE)) -> 0
...

Sheet D02
C2: Deliverable D02
C4: Use this form to document the tasks that you perform in your projects. Please, review the colour code in the "Abstract" sheet. In the exceptional case that you need to perform more tasks than expected, add them at the end.
C6: Costs | D6: Expected: | E6: =SUM(N11:N110) -> 1593.75
D7: Actual: | E7: =SUM(O11:O110) -> 1847.5
I9: Execution period | L9: Workload (in hours) | N9: Costs (in EUR)
B10: ORDER | C10: ID | D10: Type | E10: Assignee | F10: Role | G10: Activity | H10: Parent | I10: Start moment | J10: End moment | K10: Status | L10: Expected | M10: Actual | N10: Expected | O10: Actual | P10: Description
B11: 1 | C11: =IF(ISBLANK(D11), "", _xlfn.CONCAT("T", TEXT(B11, "0000"), "/", VLOOKUP(D11, Internal!$B$35:C$39, 2, FALSE), IF(OR(D11="QA", D11="Revision"), _xlfn.CONCAT("/", H11), ""))) -> T0001/M | D11: Management | E11: Student 5 | F11: Manager | G11: Initialise repository | I11: 46125.688 | J11: 46125.729 | K11: =IF(OR(I11="",J11=""),"",IF(AND(J11<>"",I11>=NOW()),"Planned",IF(AND(J11<>"",J11<NOW()),"Completed","Ongoing"))) -> Completed | L11: 1 | M11: 1 | N11: =IF(ISBLANK(L11), "", L11*VLOOKUP($F11,Internal!$B$26:$C$32,2,FALSE)) -> 50 | O11: =IF(ISBLANK(M11), "", M11*VLOOKUP($F11,Internal!$B$26:$C$32,2,FALSE)) -> 50 | P11: Create the github fork
B12: 2 | C12: =IF(ISBLANK(D12), "", _xlfn.CONCAT("T", TEXT(B12, "0000"), "/", VLOOKUP(D12, Internal!$B$35:C$39, 2, FALSE), IF(OR(D12="QA", D12="Revision"), _xlfn.CONCAT("/", H12), ""))) -> T0002/M | D12: Management | E12: Student 4 | F12: Manager | G12: Initialise repository | H12: T0001/M | I12: 46125.812 | J12: 46125.854 | K12: =IF(OR(I12="",J12=""),"",IF(AND(J12<>"",I12>=NOW()),"Planned",IF(AND(J12<>"",J12<NOW()),"Completed","Ongoing"))) -> Completed | L12: 1 | M12: 1 | N12: =IF(ISBLANK(L12), "", L12*VLOOKUP($F12,Internal!$B$26:$C$32,2,FALSE)) -> 50 | O12: =IF(ISBLANK(M12), "", M12*VLOOKUP($F12,Internal!$B$26:$C$32,2,FALSE)) -> 50 | P12: Upload the necesary project changes for the new framework
B13: 3 | C13: =IF(ISBLANK(D13), "", _xlfn.CONCAT("T", TEXT(B13, "0000"), "/", VLOOKUP(D13, Internal!$B$35:C$39, 2, FALSE), IF(OR(D13="QA", D13="Revision"), _xlfn.CONCAT("/", H13), ""))) -> T0003/M | D13: Management | E13: Student 5 | F13: Analyst | G13: Elicit requirements | I13: 46132.764 | J13: 46132.819 | K13: =IF(OR(I13="",J13=""),"",IF(AND(J13<>"",I13>=NOW()),"Planned",IF(AND(J13<>"",J13<NOW()),"Completed","Ongoing"))) -> Completed | L13: 1 | M13: 1.3333333 | N13: =IF(ISBLANK(L13), "", L13*VLOOKUP($F13,Internal!$B$26:$C$32,2,FALSE)) -> 40 | O13: =IF(ISBLANK(M13), "", M13*VLOOKUP($F13,Internal!$B$26:$C$32,2,FALSE)) -> 53.333332
B14: 4 | C14: =IF(ISBLANK(D14), "", _xlfn.CONCAT("T", TEXT(B14, "0000"), "/", VLOOKUP(D14, Internal!$B$35:C$39, 2, FALSE), IF(OR(D14="QA", D14="Revision"), _xlfn.CONCAT("/", H14), ""))) -> T0004/M | D14: Management | E14: Student 5 | F14: Analyst | G14: Write report | I14: 46132.819 | J14: 46132.847 | K14: =IF(OR(I14="",J14=""),"",IF(AND(J14<>"",I14>=NOW()),"Planned",IF(AND(J14<>"",J14<NOW()),"Completed","Ongoing"))) -> Completed | L14: 1 | M14: 0.6666666 | N14: =IF(ISBLANK(L14), "", L14*VLOOKUP($F14,Internal!$B$26:$C$32,2,FALSE)) -> 40 | O14: =IF(ISBLANK(M14), "", M14*VLOOKUP($F14,Internal!$B$26:$C$32,2,FALSE)) -> 26.666664
B15: 5 | C15: =IF(ISBLANK(D15), "", _xlfn.CONCAT("T", TEXT(B15, "0000"), "/", VLOOKUP(D15, Internal!$B$35:C$39, 2, FALSE), IF(OR(D15="QA", D15="Revision"), _xlfn.CONCAT("/", H15), ""))) -> T0005/M | D15: Management | E15: Student 1 | F15: Analyst | G15: Create domain model | H15: T0003/M | I15: 46132.833 | J15: 46132.917 | K15: =IF(OR(I15="",J15=""),"",IF(AND(J15<>"",I15>=NOW()),"Planned",IF(AND(J15<>"",J15<NOW()),"Completed","Ongoing"))) -> Completed | L15: 1.5 | M15: 2 | N15: =IF(ISBLANK(L15), "", L15*VLOOKUP($F15,Internal!$B$26:$C$32,2,FALSE)) -> 60 | O15: =IF(ISBLANK(M15), "", M15*VLOOKUP($F15,Internal!$B$26:$C$32,2,FALSE)) -> 80
B16: 6 | C16: =IF(ISBLANK(D16), "", _xlfn.CONCAT("T", TEXT(B16, "0000"), "/", VLOOKUP(D16, Internal!$B$35:C$39, 2, FALSE), IF(OR(D16="QA", D16="Revision"), _xlfn.CONCAT("/", H16), ""))) -> T0006/D | D16: Development | E16: Student 5 | F16: Developer | G16: Implement feature | I16: 46136.5 | J16: 46136.542 | K16: =IF(OR(I16="",J16=""),"",IF(AND(J16<>"",I16>=NOW()),"Planned",IF(AND(J16<>"",J16<NOW()),"Completed","Ongoing"))) -> Completed | L16: 2 | M16: 1 | N16: =IF(ISBLANK(L16), "", L16*VLOOKUP($F16,Internal!$B$26:$C$32,2,FALSE)) -> 50 | O16: =IF(ISBLANK(M16), "", M16*VLOOKUP($F16,Internal!$B$26:$C$32,2,FALSE)) -> 25 | P16: Create AdBanners requirements B5
B17: 7 | C17: =IF(ISBLANK(D17), "", _xlfn.CONCAT("T", TEXT(B17, "0000"), "/", VLOOKUP(D17, Internal!$B$35:C$39, 2, FALSE), IF(OR(D17="QA", D17="Revision"), _xlfn.CONCAT("/", H17), ""))) -> T0007/M | D17: Management | E17: Student 5 | F17: Manager | G17: Write report | I17: 46136.562 | J17: 46136.594 | K17: =IF(OR(I17="",J17=""),"",IF(AND(J17<>"",I17>=NOW()),"Planned",IF(AND(J17<>"",J17<NOW()),"Completed","Ongoing"))) -> Completed | L17: 1 | M17: 0.75 | N17: =IF(ISBLANK(L17), "", L17*VLOOKUP($F17,Internal!$B$26:$C$32,2,FALSE)) -> 50 | O17: =IF(ISBLANK(M17), "", M17*VLOOKUP($F17,Internal!$B$26:$C$32,2,FALSE)) -> 37.5
B18: 8 | C18: =IF(ISBLANK(D18), "", _xlfn.CONCAT("T", TEXT(B18, "0000"), "/", VLOOKUP(D18, Internal!$B$35:C$39, 2, FALSE), IF(OR(D18="QA", D18="Revision"), _xlfn.CONCAT("/", H18), ""))) -> T0008/D | D18: Development | E18: Student 1 | F18: Developer | G18: Implement feature | I18: 46136.417 | J18: 46136.497 | K18: =IF(OR(I18="",J18=""),"",IF(AND(J18<>"",I18>=NOW()),"Planned",IF(AND(J18<>"",J18<NOW()),"Completed","Ongoing"))) -> Completed | L18: 1 | M18: 1 | N18: =IF(ISBLANK(L18), "", L18*VLOOKUP($F18,Internal!$B$26:$C$32,2,FALSE)) -> 25 | O18: =IF(ISBLANK(M18), "", M18*VLOOKUP($F18,Internal!$B$26:$C$32,2,FALSE)) -> 25 | P18: Create project class requirements B2
B19: 9 | C19: =IF(ISBLANK(D19), "", _xlfn.CONCAT("T", TEXT(B19, "0000"), "/", VLOOKUP(D19, Internal!$B$35:C$39, 2, FALSE), IF(OR(D19="QA", D19="Revision"), _xlfn.CONCAT("/", H19), ""))) -> T0009/D | D19: Development | E19: Student 5 | F19: Developer | G19: Implement feature | I19: 46137.375 | J19: 46137.75 | K19: =IF(OR(I19="",J19=""),"",IF(AND(J19<>"",I19>=NOW()),"Planned",IF(AND(J19<>"",J19<NOW()),"Completed","Ongoing"))) -> Completed | L19: 1.5 | M19: 1 | N19: =IF(ISBLANK(L19), "", L19*VLOOKUP($F19,Internal!$B$26:$C$32,2,FALSE)) -> 37.5 | O19: =IF(ISBLANK(M19), "", M19*VLOOKUP($F19,Internal!$B$26:$C$32,2,FALSE)) -> 25 | P19: Display ad banners B12
B20: 10 | C20: =IF(ISBLANK(D20), "", _xlfn.CONCAT("T", TEXT(B20, "0000"), "/", VLOOKUP(D20, Internal!$B$35:C$39, 2, FALSE), IF(OR(D20="QA", D20="Revision"), _xlfn.CONCAT("/", H20), ""))) -> T0010/R/T0009/D | D20: Revision | E20: Student 3 | F20: Developer | G20: Test feature informally | H20: T0009/D | I20: 46138.5 | J20: 46138.51 | K20: =IF(OR(I20="",J20=""),"",IF(AND(J20<>"",I20>=NOW()),"Planned",IF(AND(J20<>"",J20<NOW()),"Completed","Ongoing"))) -> Completed | L20: 0.5 | M20: 0.25 | N20: =IF(ISBLANK(L20), "", L20*VLOOKUP($F20,Internal!$B$26:$C$32,2,FALSE)) -> 12.5 | O20: =IF(ISBLANK(M20), "", M20*VLOOKUP($F20,Internal!$B$26:$C$32,2,FALSE)) -> 6.25 | P20: Review B5 y B12
B21: 11 | C21: =IF(ISBLANK(D21), "", _xlfn.CONCAT("T", TEXT(B21, "0000"), "/", VLOOKUP(D21, Internal!$B$35:C$39, 2, FALSE), IF(OR(D21="QA", D21="Revision"), _xlfn.CONCAT("/", H21), ""))) -> T0011/D | D21: Development | E21: Student 3 | F21: Developer | G21: Implement feature | I21: 46138.521 | J21: 46138.583 | K21: =IF(OR(I21="",J21=""),"",IF(AND(J21<>"",I21>=NOW()),"Planned",IF(AND(J21<>"",J21<NOW()),"Completed","Ongoing"))) -> Completed | L21: 1.5 | M21: 1.5 | N21: =IF(ISBLANK(L21), "", L21*VLOOKUP($F21,Internal!$B$26:$C$32,2,FALSE)) -> 37.5 | O21: =IF(ISBLANK(M21), "", M21*VLOOKUP($F21,Internal!$B$26:$C$32,2,FALSE)) -> 37.5 | P21: Create member squad and Multiplicities & Constraints B3 y B4
B22: 12 | C22: =IF(ISBLANK(D22), "", _xlfn.CONCAT("T", TEXT(B22, "0000"), "/", VLOOKUP(D22, Internal!$B$35:C$39, 2, FALSE), IF(OR(D22="QA", D22="Revision"), _xlfn.CONCAT("/", H22), ""))) -> T0012/QA/ | D22: QA | E22: ALL | F22: Student | G22: Attend lecture | I22: 46139.646 | J22: 46139.722 | K22: =IF(OR(I22="",J22=""),"",IF(AND(J22<>"",I22>=NOW()),"Planned",IF(AND(J22<>"",J22<NOW()),"Completed","Ongoing"))) -> Completed | L22: 2 | M22: 2 | N22: =IF(ISBLANK(L22), "", L22*VLOOKUP($F22,Internal!$B$26:$C$32,2,FALSE)) -> 0 | O22: =IF(ISBLANK(M22), "", M22*VLOOKUP($F22,Internal!$B$26:$C$32,2,FALSE)) -> 0
B23: 13 | C23: =IF(ISBLANK(D23), "", _xlfn.CONCAT("T", TEXT(B23, "0000"), "/", VLOOKUP(D23, Internal!$B$35:C$39, 2, FALSE), IF(OR(D23="QA", D23="Revision"), _xlfn.CONCAT("/", H23), ""))) -> T0013/QA/T0008/D | D23: QA | E23: Student 1 | F23: Tester | G23: Other (Describe) | H23: T0008/D | I23: 46139.646 | J23: 46139.833 | K23: =IF(OR(I23="",J23=""),"",IF(AND(J23<>"",I23>=NOW()),"Planned",IF(AND(J23<>"",J23<NOW()),"Completed","Ongoing"))) -> Completed | L23: 2 | M23: 2.5 | N23: =IF(ISBLANK(L23), "", L23*VLOOKUP($F23,Internal!$B$26:$C$32,2,FALSE)) -> 60 | O23: =IF(ISBLANK(M23), "", M23*VLOOKUP($F23,Internal!$B$26:$C$32,2,FALSE)) -> 75 | P23: Populate sample data of Project, Member and WorksIn
B24: 14 | C24: =IF(ISBLANK(D24), "", _xlfn.CONCAT("T", TEXT(B24, "0000"), "/", VLOOKUP(D24, Internal!$B$35:C$39, 2, FALSE), IF(OR(D24="QA", D24="Revision"), _xlfn.CONCAT("/", H24), ""))) -> T0014/D | D24: Development | E24: Student 1 | F24: Developer | G24: Implement feature | I24: 46140.375 | J24: 46141.722 | K24: =IF(OR(I24="",J24=""),"",IF(AND(J24<>"",I24>=NOW()),"Planned",IF(AND(J24<>"",J24<NOW()),"Completed","Ongoing"))) -> Completed | L24: 5 | M24: 5 | N24: =IF(ISBLANK(L24), "", L24*VLOOKUP($F24,Internal!$B$26:$C$32,2,FALSE)) -> 125 | O24: =IF(ISBLANK(M24), "", M24*VLOOKUP($F24,Internal!$B$26:$C$32,2,FALSE)) -> 125 | P24: Feature list project and their components of member's projects B6
B25: 15 | C25: =IF(ISBLANK(D25), "", _xlfn.CONCAT("T", TEXT(B25, "0000"), "/", VLOOKUP(D25, Internal!$B$35:C$39, 2, FALSE), IF(OR(D25="QA", D25="Revision"), _xlfn.CONCAT("/", H25), ""))) -> T0015/R/T0014/D | D25: Revision | E25: Student 4 | F25: Developer | G25: Test feature informally | H25: T0014/D | I25: 46141.521 | J25: 46141.531 | K25: =IF(OR(I25="",J25=""),"",IF(AND(J25<>"",I25>=NOW()),"Planned",IF(AND(J25<>"",J25<NOW()),"Completed","Ongoing"))) -> Completed | L25: 0.5 | M25: 0.25 | N25: =IF(ISBLANK(L25), "", L25*VLOOKUP($F25,Internal!$B$26:$C$32,2,FALSE)) -> 12.5 | O25: =IF(ISBLANK(M25), "", M25*VLOOKUP($F25,Internal!$B$26:$C$32,2,FALSE)) -> 6.25
B26: 16 | C26: =IF(ISBLANK(D26), "", _xlfn.CONCAT("T", TEXT(B26, "0000"), "/", VLOOKUP(D26, Internal!$B$35:C$39, 2, FALSE), IF(OR(D26="QA", D26="Revision"), _xlfn.CONCAT("/", H26), ""))) -> T0016/D | D26: Development | E26: Student 1 | F26: Developer | G26: Implement feature | I26: 46142.417 | J26: 46143.833 | K26: =IF(OR(I26="",J26=""),"",IF(AND(J26<>"",I26>=NOW()),"Planned",IF(AND(J26<>"",J26<NOW()),"Completed","Ongoing"))) -> Completed | L26: 3 | M26: 4 | N26: =IF(ISBLANK(L26), "", L26*VLOOKUP($F26,Internal!$B$26:$C$32,2,FALSE)) -> 75 | O26: =IF(ISBLANK(M26), "", M26*VLOOKUP($F26,Internal!$B$26:$C$32,2,FALSE)) -> 100 | P26: Feature list project and their components of managers's projects B10
B27: 17 | C27: =IF(ISBLANK(D27), "", _xlfn.CONCAT("T", TEXT(B27, "0000"), "/", VLOOKUP(D27, Internal!$B$35:C$39, 2, FALSE), IF(OR(D27="QA", D27="Revision"), _xlfn.CONCAT("/", H27), ""))) -> T0017/QA/ | D27: QA | E27: ALL | F27: Student | G27: Attend lecture | I27: 46142.736 | J27: 46142.812 | K27: =IF(OR(I27="",J27=""),"",IF(AND(J27<>"",I27>=NOW()),"Planned",IF(AND(J27<>"",J27<NOW()),"Completed","Ongoing"))) -> Completed | L27: 2 | M27: 2 | N27: =IF(ISBLANK(L27), "", L27*VLOOKUP($F27,Internal!$B$26:$C$32,2,FALSE)) -> 0 | O27: =IF(ISBLANK(M27), "", M27*VLOOKUP($F27,Internal!$B$26:$C$32,2,FALSE)) -> 0
B28: 18 | C28: =IF(ISBLANK(D28), "", _xlfn.CONCAT("T", TEXT(B28, "0000"), "/", VLOOKUP(D28, Internal!$B$35:C$39, 2, FALSE), IF(OR(D28="QA", D28="Revision"), _xlfn.CONCAT("/", H28), ""))) -> T0018/D | D28: Development | E28: Student 3 | F28: Developer | G28: Implement feature | I28: 46142.833 | J28: 46143.5 | K28: =IF(OR(I28="",J28=""),"",IF(AND(J28<>"",I28>=NOW()),"Planned",IF(AND(J28<>"",J28<NOW()),"Completed","Ongoing"))) -> Completed | L28: 4 | M28: 5 | N28: =IF(ISBLANK(L28), "", L28*VLOOKUP($F28,Internal!$B$26:$C$32,2,FALSE)) -> 100 | O28: =IF(ISBLANK(M28), "", M28*VLOOKUP($F28,Internal!$B$26:$C$32,2,FALSE)) -> 125 | P28: Feature Dashoard B11
B29: 19 | C29: =IF(ISBLANK(D29), "", _xlfn.CONCAT("T", TEXT(B29, "0000"), "/", VLOOKUP(D29, Internal!$B$35:C$39, 2, FALSE), IF(OR(D29="QA", D29="Revision"), _xlfn.CONCAT("/", H29), ""))) -> T0019/D | D29: Development | E29: Student 5 | F29: Developer | G29: Test feature informally | H29: T0016/D | I29: 46144.375 | J29: 46144.385 | K29: =IF(OR(I29="",J29=""),"",IF(AND(J29<>"",I29>=NOW()),"Planned",IF(AND(J29<>"",J29<NOW()),"Completed","Ongoing"))) -> Completed | L29: 0.5 | M29: 0.25 | N29: =IF(ISBLANK(L29), "", L29*VLOOKUP($F29,Internal!$B$26:$C$32,2,FALSE)) -> 12.5 | O29: =IF(ISBLANK(M29), "", M29*VLOOKUP($F29,Internal!$B$26:$C$32,2,FALSE)) -> 6.25
B30: 20 | C30: =IF(ISBLANK(D30), "", _xlfn.CONCAT("T", TEXT(B30, "0000"), "/", VLOOKUP(D30, Internal!$B$35:C$39, 2, FALSE), IF(OR(D30="QA", D30="Revision"), _xlfn.CONCAT("/", H30), ""))) -> T0020/D | D30: Development | E30: Student 4 | F30: Developer | G30: Test feature informally | H30: T0018/D | I30: 46144.5 | J30: 46144.51 | K30: =IF(OR(I30="",J30=""),"",IF(AND(J30<>"",I30>=NOW()),"Planned",IF(AND(J30<>"",J30<NOW()),"Completed","Ongoing"))) -> Completed | L30: 0.25 | M30: 0.25 | N30: =IF(ISBLANK(L30), "", L30*VLOOKUP($F30,Internal!$B$26:$C$32,2,FALSE)) -> 6.25 | O30: =IF(ISBLANK(M30), "", M30*VLOOKUP($F30,Internal!$B$26:$C$32,2,FALSE)) -> 6.25
B31: 21 | C31: =IF(ISBLANK(D31), "", _xlfn.CONCAT("T", TEXT(B31, "0000"), "/", VLOOKUP(D31, Internal!$B$35:C$39, 2, FALSE), IF(OR(D31="QA", D31="Revision"), _xlfn.CONCAT("/", H31), ""))) -> T0021/D | D31: Development | E31: Student 3 | F31: Developer | G31: Implement feature | H31: T0018/D | I31: 46147.375 | J31: 46147.5 | K31: =IF(OR(I31="",J31=""),"",IF(AND(J31<>"",I31>=NOW()),"Planned",IF(AND(J31<>"",J31<NOW()),"Completed","Ongoing"))) -> Completed | L31: 1 | M31: 1.5 | N31: =IF(ISBLANK(L31), "", L31*VLOOKUP($F31,Internal!$B$26:$C$32,2,FALSE)) -> 25 | O31: =IF(ISBLANK(M31), "", M31*VLOOKUP($F31,Internal!$B$26:$C$32,2,FALSE)) -> 37.5 | P31: Fix views and repository dashboard
B32: 22 | C32: =IF(ISBLANK(D32), "", _xlfn.CONCAT("T", TEXT(B32, "0000"), "/", VLOOKUP(D32, Internal!$B$35:C$39, 2, FALSE), IF(OR(D32="QA", D32="Revision"), _xlfn.CONCAT("/", H32), ""))) -> T0022/D | D32: Development | E32: Student 1 | F32: Developer | G32: Implement feature | I32: 46145.417 | J32: 46146.958 | K32: =IF(OR(I32="",J32=""),"",IF(AND(J32<>"",I32>=NOW()),"Planned",IF(AND(J32<>"",J32<NOW()),"Completed","Ongoing"))) -> Completed | L32: 5 | M32: 7 | N32: =IF(ISBLANK(L32), "", L32*VLOOKUP($F32,Internal!$B$26:$C$32,2,FALSE)) -> 125 | O32: =IF(ISBLANK(M32), "", M32*VLOOKUP($F32,Internal!$B$26:$C$32,2,FALSE)) -> 175 | P32: Feature of views Any, Authenticated and CRUD manager B8, B9 y B10
B33: 23 | C33: =IF(ISBLANK(D33), "", _xlfn.CONCAT("T", TEXT(B33, "0000"), "/", VLOOKUP(D33, Internal!$B$35:C$39, 2, FALSE), IF(OR(D33="QA", D33="Revision"), _xlfn.CONCAT("/", H33), ""))) -> T0023/QA/ | D33: QA | E33: ALL | F33: Student | G33: Attend lecture | I33: 46146.646 | J33: 46146.729 | K33: =IF(OR(I33="",J33=""),"",IF(AND(J33<>"",I33>=NOW()),"Planned",IF(AND(J33<>"",J33<NOW()),"Completed","Ongoing"))) -> Completed | L33: 2 | M33: 2 | N33: =IF(ISBLANK(L33), "", L33*VLOOKUP($F33,Internal!$B$26:$C$32,2,FALSE)) -> 0 | O33: =IF(ISBLANK(M33), "", M33*VLOOKUP($F33,Internal!$B$26:$C$32,2,FALSE)) -> 0
B34: 24 | C34: =IF(ISBLANK(D34), "", _xlfn.CONCAT("T", TEXT(B34, "0000"), "/", VLOOKUP(D34, Internal!$B$35:C$39, 2, FALSE), IF(OR(D34="QA", D34="Revision"), _xlfn.CONCAT("/", H34), ""))) -> T0024/R/T0022/D | D34: Revision | E34: Student 4 | F34: Developer | G34: Test feature informally | H34: T0022/D | I34: 46147.375 | J34: 46147.458 | K34: =IF(OR(I34="",J34=""),"",IF(AND(J34<>"",I34>=NOW()),"Planned",IF(AND(J34<>"",J34<NOW()),"Completed","Ongoing"))) -> Completed | L34: 0.5 | M34: 1.5 | N34: =IF(ISBLANK(L34), "", L34*VLOOKUP($F34,Internal!$B$26:$C$32,2,FALSE)) -> 12.5 | O34: =IF(ISBLANK(M34), "", M34*VLOOKUP($F34,Internal!$B$26:$C$32,2,FALSE)) -> 37.5 | P34: Review B10
B35: 25 | C35: =IF(ISBLANK(D35), "", _xlfn.CONCAT("T", TEXT(B35, "0000"), "/", VLOOKUP(D35, Internal!$B$35:C$39, 2, FALSE), IF(OR(D35="QA", D35="Revision"), _xlfn.CONCAT("/", H35), ""))) -> T0025/R/T0022/D | D35: Revision | E35: Student 5 | F35: Developer | G35: Test feature informally | H35: T0022/D | I35: 46147.417 | J35: 46147.458 | K35: =IF(OR(I35="",J35=""),"",IF(AND(J35<>"",I35>=NOW()),"Planned",IF(AND(J35<>"",J35<NOW()),"Completed","Ongoing"))) -> Completed | L35: 0.5 | M35: 1 | N35: =IF(ISBLANK(L35), "", L35*VLOOKUP($F35,Internal!$B$26:$C$32,2,FALSE)) -> 12.5 | O35: =IF(ISBLANK(M35), "", M35*VLOOKUP($F35,Internal!$B$26:$C$32,2,FALSE)) -> 25 | P35: Review B8 y B9
B36: 26 | C36: =IF(ISBLANK(D36), "", _xlfn.CONCAT("T", TEXT(B36, "0000"), "/", VLOOKUP(D36, Internal!$B$35:C$39, 2, FALSE), IF(OR(D36="QA", D36="Revision"), _xlfn.CONCAT("/", H36), ""))) -> T0026/D | D36: Development | E36: Student 5 | F36: Developer | G36: Implement feature | I36: 46148.521 | J36: 46148.823 | K36: =IF(OR(I36="",J36=""),"",IF(AND(J36<>"",I36>=NOW()),"Planned",IF(AND(J36<>"",J36<NOW()),"Completed","Ongoing"))) -> Completed | L36: 2 | M36: 2.25 | N36: =IF(ISBLANK(L36), "", L36*VLOOKUP($F36,Internal!$B$26:$C$32,2,FALSE)) -> 50 | O36: =IF(ISBLANK(M36), "", M36*VLOOKUP($F36,Internal!$B$26:$C$32,2,FALSE)) -> 56.25 | P36: And view members in Member and Manager
B37: 27 | C37: =IF(ISBLANK(D37), "", _xlfn.CONCAT("T", TEXT(B37, "0000"), "/", VLOOKUP(D37, Internal!$B$35:C$39, 2, FALSE), IF(OR(D37="QA", D37="Revision"), _xlfn.CONCAT("/", H37), ""))) -> T0027/D | D37: Development | E37: Student 3 | F37: Developer | G37: Implement feature | I37: 46148.542 | J37: 46148.646 | K37: =IF(OR(I37="",J37=""),"",IF(AND(J37<>"",I37>=NOW()),"Planned",IF(AND(J37<>"",J37<NOW()),"Completed","Ongoing"))) -> Completed | L37: 1 | M37: 0.75 | N37: =IF(ISBLANK(L37), "", L37*VLOOKUP($F37,Internal!$B$26:$C$32,2,FALSE)) -> 25 | O37: =IF(ISBLANK(M37), "", M37*VLOOKUP($F37,Internal!$B$26:$C$32,2,FALSE)) -> 18.75 | P37: Fix dashboard
B38: 28 | C38: =IF(ISBLANK(D38), "", _xlfn.CONCAT("T", TEXT(B38, "0000"), "/", VLOOKUP(D38, Internal!$B$35:C$39, 2, FALSE), IF(OR(D38="QA", D38="Revision"), _xlfn.CONCAT("/", H38), ""))) -> T0028/D | D38: Development | E38: Student 1 | F38: Developer | G38: Implement feature | I38: 46148.646 | J38: 46150.167 | K38: =IF(OR(I38="",J38=""),"",IF(AND(J38<>"",I38>=NOW()),"Planned",IF(AND(J38<>"",J38<NOW()),"Completed","Ongoing"))) -> Completed | L38: 5 | M38: 8 | N38: =IF(ISBLANK(L38), "", L38*VLOOKUP($F38,Internal!$B$26:$C$32,2,FALSE)) -> 125 | O38: =IF(ISBLANK(M38), "", M38*VLOOKUP($F38,Internal!$B$26:$C$32,2,FALSE)) -> 200 | P38: Add and delete memebers of a project
B39: 29 | C39: =IF(ISBLANK(D39), "", _xlfn.CONCAT("T", TEXT(B39, "0000"), "/", VLOOKUP(D39, Internal!$B$35:C$39, 2, FALSE), IF(OR(D39="QA", D39="Revision"), _xlfn.CONCAT("/", H39), ""))) -> T0029/D | D39: Development | E39: Student 4 | F39: Developer | G39: Implement feature | I39: 46149.5 | J39: 46149.958 | K39: =IF(OR(I39="",J39=""),"",IF(AND(J39<>"",I39>=NOW()),"Planned",IF(AND(J39<>"",J39<NOW()),"Completed","Ongoing"))) -> Completed | L39: 3 | M39: 4 | N39: =IF(ISBLANK(L39), "", L39*VLOOKUP($F39,Internal!$B$26:$C$32,2,FALSE)) -> 75 | O39: =IF(ISBLANK(M39), "", M39*VLOOKUP($F39,Internal!$B$26:$C$32,2,FALSE)) -> 100 | P39: Views members in Any-Authenticated and fix in this views but in Member and Manager
B40: 30 | C40: =IF(ISBLANK(D40), "", _xlfn.CONCAT("T", TEXT(B40, "0000"), "/", VLOOKUP(D40, Internal!$B$35:C$39, 2, FALSE), IF(OR(D40="QA", D40="Revision"), _xlfn.CONCAT("/", H40), ""))) -> T0030/QA/ | D40: QA | E40: ALL | F40: Student | G40: Attend lecture | I40: 46149.736 | J40: 46149.812 | K40: =IF(OR(I40="",J40=""),"",IF(AND(J40<>"",I40>=NOW()),"Planned",IF(AND(J40<>"",J40<NOW()),"Completed","Ongoing"))) -> Completed | L40: 2 | M40: 2 | N40: =IF(ISBLANK(L40), "", L40*VLOOKUP($F40,Internal!$B$26:$C$32,2,FALSE)) -> 0 | O40: =IF(ISBLANK(M40), "", M40*VLOOKUP($F40,Internal!$B$26:$C$32,2,FALSE)) -> 0
B41: 31 | C41: =IF(ISBLANK(D41), "", _xlfn.CONCAT("T", TEXT(B41, "0000"), "/", VLOOKUP(D41, Internal!$B$35:C$39, 2, FALSE), IF(OR(D41="QA", D41="Revision"), _xlfn.CONCAT("/", H41), ""))) -> T0031/R/ | D41: Revision | E41: Student 5 | F41: Tester | G41: Test feature formally | I41: 46150.375 | J41: 46150.938 | K41: =IF(OR(I41="",J41=""),"",IF(AND(J41<>"",I41>=NOW()),"Planned",IF(AND(J41<>"",J41<NOW()),"Completed","Ongoing"))) -> Completed | L41: 5 | M41: 6 | N41: =IF(ISBLANK(L41), "", L41*VLOOKUP($F41,Internal!$B$26:$C$32,2,FALSE)) -> 150 | O41: =IF(ISBLANK(M41), "", M41*VLOOKUP($F41,Internal!$B$26:$C$32,2,FALSE)) -> 180
B42: 32 | C42: =IF(ISBLANK(D42), "", _xlfn.CONCAT("T", TEXT(B42, "0000"), "/", VLOOKUP(D42, Internal!$B$35:C$39, 2, FALSE), IF(OR(D42="QA", D42="Revision"), _xlfn.CONCAT("/", H42), ""))) -> T0032/R/ | D42: Revision | E42: Student 5 | F42: Tester | G42: Test performance formally | I42: 46150.5 | J42: 46150.938 | K42: =IF(OR(I42="",J42=""),"",IF(AND(J42<>"",I42>=NOW()),"Planned",IF(AND(J42<>"",J42<NOW()),"Completed","Ongoing"))) -> Completed | L42: 4 | M42: 4 | N42: =IF(ISBLANK(L42), "", L42*VLOOKUP($F42,Internal!$B$26:$C$32,2,FALSE)) -> 120 | O42: =IF(ISBLANK(M42), "", M42*VLOOKUP($F42,Internal!$B$26:$C$32,2,FALSE)) -> 120
B43: 33 | C43: =IF(ISBLANK(D43), "", _xlfn.CONCAT("T", TEXT(B43, "0000"), "/", VLOOKUP(D43, Internal!$B$35:C$39, 2, FALSE), IF(OR(D43="QA", D43="Revision"), _xlfn.CONCAT("/", H43), ""))) -> T0033/QA/ | D43: QA | E43: Student 5 | F43: Tester | G43: Write report | I43: 46150.938 | J43: 46150.958 | K43: =IF(OR(I43="",J43=""),"",IF(AND(J43<>"",I43>=NOW()),"Planned",IF(AND(J43<>"",J43<NOW()),"Completed","Ongoing"))) -> Completed | L43: 1 | M43: 1.25 | N43: =IF(ISBLANK(L43), "", L43*VLOOKUP($F43,Internal!$B$26:$C$32,2,FALSE)) -> 30 | O43: =IF(ISBLANK(M43), "", M43*VLOOKUP($F43,Internal!$B$26:$C$32,2,FALSE)) -> 37.5
B44: 34 | C44: =IF(ISBLANK(D44), "", _xlfn.CONCAT("T", TEXT(B44, "0000"), "/", VLOOKUP(D44, Internal!$B$35:C$39, 2, FALSE), IF(OR(D44="QA", D44="Revision"), _xlfn.CONCAT("/", H44), ""))) | K44: =IF(OR(I44="",J44=""),"",IF(AND(J44<>"",I44>=NOW()),"Planned",IF(AND(J44<>"",J44<NOW()),"Completed","Ongoing"))) | N44: =IF(ISBLANK(L44), "", L44*VLOOKUP($F44,Internal!$B$26:$C$32,2,FALSE)) | O44: =IF(ISBLANK(M44), "", M44*VLOOKUP($F44,Internal!$B$26:$C$32,2,FALSE))
...

Sheet D03
C2: Deliverable D03
C4: Use this form to document the tasks that you perform in your projects. Please, review the colour code in the "Abstract" sheet. In the exceptional case that you need to perform more tasks than expected, add them at the end.
C6: Costs | D6: Expected: | E6: =SUM(N11:N110) -> 0
D7: Actual: | E7: =SUM(O11:O110) -> 0
I9: Execution period | L9: Workload (in hours) | N9: Costs (in EUR)
B10: ORDER | C10: ID | D10: Type | E10: Assignee | F10: Role | G10: Activity | H10: Parent | I10: Start moment | J10: End moment | K10: Status | L10: Expected | M10: Actual | N10: Expected | O10: Actual | P10: Description
B11: 1 | C11: =IF(ISBLANK(D11), "", _xlfn.CONCAT("T", TEXT(B11, "0000"), "/", VLOOKUP(D11, Internal!$B$35:C$39, 2, FALSE), IF(OR(D11="QA", D11="Revision"), _xlfn.CONCAT("/", H11), ""))) | K11: =IF(OR(I11="",J11=""),"",IF(AND(J11<>"",I11>=NOW()),"Planned",IF(AND(J11<>"",J11<NOW()),"Completed","Ongoing"))) | N11: =IF(ISBLANK(L11), "", L11*VLOOKUP($F11,Internal!$B$26:$C$32,2,FALSE)) | O11: =IF(ISBLANK(M11), "", M11*VLOOKUP($F11,Internal!$B$26:$C$32,2,FALSE))
B12: 2 | C12: =IF(ISBLANK(D12), "", _xlfn.CONCAT("T", TEXT(B12, "0000"), "/", VLOOKUP(D12, Internal!$B$35:C$39, 2, FALSE), IF(OR(D12="QA", D12="Revision"), _xlfn.CONCAT("/", H12), ""))) | K12: =IF(OR(I12="",J12=""),"",IF(AND(J12<>"",I12>=NOW()),"Planned",IF(AND(J12<>"",J12<NOW()),"Completed","Ongoing"))) | N12: =IF(ISBLANK(L12), "", L12*VLOOKUP($F12,Internal!$B$26:$C$32,2,FALSE)) | O12: =IF(ISBLANK(M12), "", M12*VLOOKUP($F12,Internal!$B$26:$C$32,2,FALSE))
B13: 3 | C13: =IF(ISBLANK(D13), "", _xlfn.CONCAT("T", TEXT(B13, "0000"), "/", VLOOKUP(D13, Internal!$B$35:C$39, 2, FALSE), IF(OR(D13="QA", D13="Revision"), _xlfn.CONCAT("/", H13), ""))) | K13: =IF(OR(I13="",J13=""),"",IF(AND(J13<>"",I13>=NOW()),"Planned",IF(AND(J13<>"",J13<NOW()),"Completed","Ongoing"))) | N13: =IF(ISBLANK(L13), "", L13*VLOOKUP($F13,Internal!$B$26:$C$32,2,FALSE)) | O13: =IF(ISBLANK(M13), "", M13*VLOOKUP($F13,Internal!$B$26:$C$32,2,FALSE))
B14: 4 | C14: =IF(ISBLANK(D14), "", _xlfn.CONCAT("T", TEXT(B14, "0000"), "/", VLOOKUP(D14, Internal!$B$35:C$39, 2, FALSE), IF(OR(D14="QA", D14="Revision"), _xlfn.CONCAT("/", H14), ""))) | K14: =IF(OR(I14="",J14=""),"",IF(AND(J14<>"",I14>=NOW()),"Planned",IF(AND(J14<>"",J14<NOW()),"Completed","Ongoing"))) | N14: =IF(ISBLANK(L14), "", L14*VLOOKUP($F14,Internal!$B$26:$C$32,2,FALSE)) | O14: =IF(ISBLANK(M14), "", M14*VLOOKUP($F14,Internal!$B$26:$C$32,2,FALSE))
B15: 5 | C15: =IF(ISBLANK(D15), "", _xlfn.CONCAT("T", TEXT(B15, "0000"), "/", VLOOKUP(D15, Internal!$B$35:C$39, 2, FALSE), IF(OR(D15="QA", D15="Revision"), _xlfn.CONCAT("/", H15), ""))) | K15: =IF(OR(I15="",J15=""),"",IF(AND(J15<>"",I15>=NOW()),"Planned",IF(AND(J15<>"",J15<NOW()),"Completed","Ongoing"))) | N15: =IF(ISBLANK(L15), "", L15*VLOOKUP($F15,Internal!$B$26:$C$32,2,FALSE)) | O15: =IF(ISBLANK(M15), "", M15*VLOOKUP($F15,Internal!$B$26:$C$32,2,FALSE))
B16: 6 | C16: =IF(ISBLANK(D16), "", _xlfn.CONCAT("T", TEXT(B16, "0000"), "/", VLOOKUP(D16, Internal!$B$35:C$39, 2, FALSE), IF(OR(D16="QA", D16="Revision"), _xlfn.CONCAT("/", H16), ""))) | K16: =IF(OR(I16="",J16=""),"",IF(AND(J16<>"",I16>=NOW()),"Planned",IF(AND(J16<>"",J16<NOW()),"Completed","Ongoing"))) | N16: =IF(ISBLANK(L16), "", L16*VLOOKUP($F16,Internal!$B$26:$C$32,2,FALSE)) | O16: =IF(ISBLANK(M16), "", M16*VLOOKUP($F16,Internal!$B$26:$C$32,2,FALSE))
B17: 7 | C17: =IF(ISBLANK(D17), "", _xlfn.CONCAT("T", TEXT(B17, "0000"), "/", VLOOKUP(D17, Internal!$B$35:C$39, 2, FALSE), IF(OR(D17="QA", D17="Revision"), _xlfn.CONCAT("/", H17), ""))) | K17: =IF(OR(I17="",J17=""),"",IF(AND(J17<>"",I17>=NOW()),"Planned",IF(AND(J17<>"",J17<NOW()),"Completed","Ongoing"))) | N17: =IF(ISBLANK(L17), "", L17*VLOOKUP($F17,Internal!$B$26:$C$32,2,FALSE)) | O17: =IF(ISBLANK(M17), "", M17*VLOOKUP($F17,Internal!$B$26:$C$32,2,FALSE))
B18: 8 | C18: =IF(ISBLANK(D18), "", _xlfn.CONCAT("T", TEXT(B18, "0000"), "/", VLOOKUP(D18, Internal!$B$35:C$39, 2, FALSE), IF(OR(D18="QA", D18="Revision"), _xlfn.CONCAT("/", H18), ""))) | K18: =IF(OR(I18="",J18=""),"",IF(AND(J18<>"",I18>=NOW()),"Planned",IF(AND(J18<>"",J18<NOW()),"Completed","Ongoing"))) | N18: =IF(ISBLANK(L18), "", L18*VLOOKUP($F18,Internal!$B$26:$C$32,2,FALSE)) | O18: =IF(ISBLANK(M18), "", M18*VLOOKUP($F18,Internal!$B$26:$C$32,2,FALSE))
B19: 9 | C19: =IF(ISBLANK(D19), "", _xlfn.CONCAT("T", TEXT(B19, "0000"), "/", VLOOKUP(D19, Internal!$B$35:C$39, 2, FALSE), IF(OR(D19="QA", D19="Revision"), _xlfn.CONCAT("/", H19), ""))) | K19: =IF(OR(I19="",J19=""),"",IF(AND(J19<>"",I19>=NOW()),"Planned",IF(AND(J19<>"",J19<NOW()),"Completed","Ongoing"))) | N19: =IF(ISBLANK(L19), "", L19*VLOOKUP($F19,Internal!$B$26:$C$32,2,FALSE)) | O19: =IF(ISBLANK(M19), "", M19*VLOOKUP($F19,Internal!$B$26:$C$32,2,FALSE))
B20: 10 | C20: =IF(ISBLANK(D20), "", _xlfn.CONCAT("T", TEXT(B20, "0000"), "/", VLOOKUP(D20, Internal!$B$35:C$39, 2, FALSE), IF(OR(D20="QA", D20="Revision"), _xlfn.CONCAT("/", H20), ""))) | K20: =IF(OR(I20="",J20=""),"",IF(AND(J20<>"",I20>=NOW()),"Planned",IF(AND(J20<>"",J20<NOW()),"Completed","Ongoing"))) | N20: =IF(ISBLANK(L20), "", L20*VLOOKUP($F20,Internal!$B$26:$C$32,2,FALSE)) | O20: =IF(ISBLANK(M20), "", M20*VLOOKUP($F20,Internal!$B$26:$C$32,2,FALSE))
B21: 11 | C21: =IF(ISBLANK(D21), "", _xlfn.CONCAT("T", TEXT(B21, "0000"), "/", VLOOKUP(D21, Internal!$B$35:C$39, 2, FALSE), IF(OR(D21="QA", D21="Revision"), _xlfn.CONCAT("/", H21), ""))) | K21: =IF(OR(I21="",J21=""),"",IF(AND(J21<>"",I21>=NOW()),"Planned",IF(AND(J21<>"",J21<NOW()),"Completed","Ongoing"))) | N21: =IF(ISBLANK(L21), "", L21*VLOOKUP($F21,Internal!$B$26:$C$32,2,FALSE)) | O21: =IF(ISBLANK(M21), "", M21*VLOOKUP($F21,Internal!$B$26:$C$32,2,FALSE))
B22: 12 | C22: =IF(ISBLANK(D22), "", _xlfn.CONCAT("T", TEXT(B22, "0000"), "/", VLOOKUP(D22, Internal!$B$35:C$39, 2, FALSE), IF(OR(D22="QA", D22="Revision"), _xlfn.CONCAT("/", H22), ""))) | K22: =IF(OR(I22="",J22=""),"",IF(AND(J22<>"",I22>=NOW()),"Planned",IF(AND(J22<>"",J22<NOW()),"Completed","Ongoing"))) | N22: =IF(ISBLANK(L22), "", L22*VLOOKUP($F22,Internal!$B$26:$C$32,2,FALSE)) | O22: =IF(ISBLANK(M22), "", M22*VLOOKUP($F22,Internal!$B$26:$C$32,2,FALSE))
... B110: 100 | C110: =IF(ISBLANK(D110), "", _xlfn.CONCAT("T", TEXT(B110, "0000"), "/", VLOOKUP(D110, Internal!$B$35:C$39, 2, FALSE), IF(OR(D110="QA", D110="Revision"), _xlfn.CONCAT("/", H110), ""))) | K110: =IF(OR(I110="",J110=""),"",IF(AND(J110<>"",I110>=NOW()),"Planned",IF(AND(J110<>"",J110<NOW()),"Completed","Ongoing"))) | N110: =IF(ISBLANK(L110), "", L110*VLOOKUP($F110,Internal!$B$26:$C$32,2,FALSE)) | O110: =IF(ISBLANK(M110), "", M110*VLOOKUP($F110,Internal!$B$26:$C$32,2,FALSE))

Sheet Internal
B2: Internal data
B4: This sheet contains internal data that are used elsewhere to perform some checks and computations. Please, do not modify it al all.
B8: Prospective assignees
B9: Student 1
B10: Student 2
B11: Student 3
B12: Student 4
B13: Student 5
B14: ALL
B16: Statuses
B17: Planned
B18: Ongoing
... B21: Moments
B22: 45658
B23: 2100/31/12 23:59:59
B25: Roles | C25: Cost | D25: Tasks…
B26: Student | C26: 0 | D26: Attend lecture | E26: Study and train | F26: Attend work meeting | G26: Other (Describe)
B27: Manager | C27: 50 | D27: Make plans | E27: Make re-plannings | F27: Initialise repository | G27: Supervise task | H27: Write report | I27: Other (Describe)
B28: Analyst | C28: 40 | D28: Elicit requirements | E28: Define features | F28: Create domain model | G28: Write report | H28: Other (Describe)
B29: Developer | C29: 25 | D29: Create dev. config. | E29: Customise the starter | F29: Implement feature | G29: Test feature informally | H29: Write report | I29: Other (Describe)
B30: Tester | C30: 30 | D30: Check deliverable | E30: Check task | F30: Test feature formally | G30: Test performance formally | H30: Write report | I30: Other (Describe)
B31: Operator | C31: 30 | D31: Prepare dep. platf. | E31: Package deliverable | F31: Upload deliverable | G31: Deploy application | H31: Keep application running | I31: Write report | J31: Other (Describe)
B32: Other | C32: 10 | D32: Other (Describe)
B34: Task types | C34: Key
B35: Management | C35: M
B36: Development | C36: D
B37: QA | C37: QA
B38: Revision | C38: R
B39: Other | C39: O
